<robot name="lampe_test">

	<!-- Link -->

 	<link name="base_link">
		<visual>
		    <origin xyz="0 0 0" rpy="0 0 0"/>
			<geometry>
				<box size="0.3 0.3 0.1"/>
			</geometry>
			<material name="Color1">
	       		<color rgba="0 0.9 0 1"/>
	     	</material>
		</visual>	
	</link>

    <link name="base_rotate_link">
		<visual>
		    <origin xyz="0 0 0" rpy="0 0 0"/>
			<geometry>
				<box size="0.15 0.15 0.05"/>
			</geometry>
			<material name="Color2">
	       		<color rgba="0 0.9 0.9 1"/>
	     	</material>
		</visual>	
	</link>

    <link name="arm_link">
		<visual>
		    <origin xyz="0 0 0.25" rpy="0 0 0"/>
			<geometry>
				<box size="0.05 0.05 0.5"/>
			</geometry>
			<material name="Color3">
	       		<color rgba="0.9 0.9 0 1"/>
	     	</material>
		</visual>	
	</link>

    <link name="arm2_link">
		<visual>
		    <origin xyz="0 0 0.25" rpy="0 0 0"/>
			<geometry>
				<box size="0.05 0.05 0.5"/>
			</geometry>
			<material name="Color4">
	       		<color rgba="0.9 0.9 0 1"/>
	     	</material>
		</visual>	
	</link>

    <link name="head_link">
		<visual>
		    <origin xyz="0 0 0.075" rpy="0 0 0"/>
			<geometry>
				<box size="0.15 0.15 0.15"/>
			</geometry>
			<material name="Color5">
	       		<color rgba="0.9 0 0 1"/>
	     	</material>
		</visual>	
	</link>
	
	<!-- Joint -->

	<joint name="base_yaw_joint" type="revolute">
    	<parent link="base_link"/>
    	<child link="base_rotate_link"/>
    	<origin xyz="0 0 0.05" rpy="0 0 0"/>
    	<axis xyz="0 0 1"/>
    	<limit lower="-3.142" upper="3.142" effort="10" velocity="3"/>
  	</joint>

    <joint name="arm_pitch_joint" type="revolute">
    	<parent link="base_rotate_link"/>
    	<child link="arm_link"/>
    	<origin xyz="0 0 0" rpy="0.785 0 0"/>
    	<axis xyz="1 0 0"/>
    	<limit lower="-2.065" upper="0.461" effort="10" velocity="3"/>
  	</joint>

    <joint name="arm2_pitch_joint" type="revolute">
    	<parent link="arm_link"/>
    	<child link="arm2_link"/>
    	<origin xyz="0 0 0.5" rpy="-1.571 0 0"/>
    	<axis xyz="1 0 0"/>
    	<limit lower="-1.1" upper="1.571" effort="10" velocity="3"/>
  	</joint>

    <joint name="head_pitch_joint" type="revolute">
    	<parent link="arm2_link"/>
    	<child link="head_link"/>
    	<origin xyz="0 0 0.5" rpy="-0.785 0 0"/>
    	<axis xyz="1 0 0"/>
    	<limit lower="-0.785" upper="0.785" effort="10" velocity="3"/>
  	</joint>
 
</robot>
